<?xml version="1.0" encoding="UTF-8"?>
<testsuite errors="2" failures="0" name="test_basics.BasicTestCase-20180925110350" skipped="0" tests="2" time="0.045" timestamp="2018-09-25T11:03:50">
	<testcase classname="test_basics.BasicTestCase" name="test_app_exists" time="0.039" timestamp="2018-09-25T11:03:50">
		<error message="(psycopg2.OperationalError) could not translate host name &quot;db&quot; to address: nodename nor servname provided, or not known
 (Background on this error at: http://sqlalche.me/e/e3q8)" type="OperationalError">
<![CDATA[Traceback (most recent call last):
  File "/Users/levlaz/git/SupportService/venv/lib/python3.7/site-packages/sqlalchemy/engine/base.py", line 2158, in _wrap_pool_connect
    return fn()
  File "/Users/levlaz/git/SupportService/venv/lib/python3.7/site-packages/sqlalchemy/pool.py", line 400, in connect
    return _ConnectionFairy._checkout(self)
  File "/Users/levlaz/git/SupportService/venv/lib/python3.7/site-packages/sqlalchemy/pool.py", line 788, in _checkout
    fairy = _ConnectionRecord.checkout(pool)
  File "/Users/levlaz/git/SupportService/venv/lib/python3.7/site-packages/sqlalchemy/pool.py", line 529, in checkout
    rec = pool._do_get()
  File "/Users/levlaz/git/SupportService/venv/lib/python3.7/site-packages/sqlalchemy/pool.py", line 1193, in _do_get
    self._dec_overflow()
  File "/Users/levlaz/git/SupportService/venv/lib/python3.7/site-packages/sqlalchemy/util/langhelpers.py", line 66, in __exit__
    compat.reraise(exc_type, exc_value, exc_tb)
  File "/Users/levlaz/git/SupportService/venv/lib/python3.7/site-packages/sqlalchemy/util/compat.py", line 249, in reraise
    raise value
  File "/Users/levlaz/git/SupportService/venv/lib/python3.7/site-packages/sqlalchemy/pool.py", line 1190, in _do_get
    return self._create_connection()
  File "/Users/levlaz/git/SupportService/venv/lib/python3.7/site-packages/sqlalchemy/pool.py", line 347, in _create_connection
    return _ConnectionRecord(self)
  File "/Users/levlaz/git/SupportService/venv/lib/python3.7/site-packages/sqlalchemy/pool.py", line 474, in __init__
    self.__connect(first_connect_check=True)
  File "/Users/levlaz/git/SupportService/venv/lib/python3.7/site-packages/sqlalchemy/pool.py", line 671, in __connect
    connection = pool._invoke_creator(self)
  File "/Users/levlaz/git/SupportService/venv/lib/python3.7/site-packages/sqlalchemy/engine/strategies.py", line 106, in connect
    return dialect.connect(*cargs, **cparams)
  File "/Users/levlaz/git/SupportService/venv/lib/python3.7/site-packages/sqlalchemy/engine/default.py", line 412, in connect
    return self.dbapi.connect(*cargs, **cparams)
  File "/Users/levlaz/git/SupportService/venv/lib/python3.7/site-packages/psycopg2/__init__.py", line 130, in connect
    conn = _connect(dsn, connection_factory=connection_factory, **kwasync)
psycopg2.OperationalError: could not translate host name "db" to address: nodename nor servname provided, or not known


The above exception was the direct cause of the following exception:

Traceback (most recent call last):
  File "/Users/levlaz/git/SupportService/tests/test_basics.py", line 10, in setUp
    self.app = create_app('testing')
  File "/Users/levlaz/git/SupportService/app/factory.py", line 29, in create_app
    config[config_name].init_app(app)
  File "/Users/levlaz/git/SupportService/app/config.py", line 53, in init_app
    db.create_all()
  File "/Users/levlaz/git/SupportService/venv/lib/python3.7/site-packages/flask_sqlalchemy/__init__.py", line 963, in create_all
    self._execute_for_all_tables(app, bind, 'create_all')
  File "/Users/levlaz/git/SupportService/venv/lib/python3.7/site-packages/flask_sqlalchemy/__init__.py", line 955, in _execute_for_all_tables
    op(bind=self.get_engine(app, bind), **extra)
  File "/Users/levlaz/git/SupportService/venv/lib/python3.7/site-packages/sqlalchemy/sql/schema.py", line 4005, in create_all
    tables=tables)
  File "/Users/levlaz/git/SupportService/venv/lib/python3.7/site-packages/sqlalchemy/engine/base.py", line 1939, in _run_visitor
    with self._optional_conn_ctx_manager(connection) as conn:
  File "/usr/local/Cellar/python/3.7.0/Frameworks/Python.framework/Versions/3.7/lib/python3.7/contextlib.py", line 112, in __enter__
    return next(self.gen)
  File "/Users/levlaz/git/SupportService/venv/lib/python3.7/site-packages/sqlalchemy/engine/base.py", line 1932, in _optional_conn_ctx_manager
    with self.contextual_connect() as conn:
  File "/Users/levlaz/git/SupportService/venv/lib/python3.7/site-packages/sqlalchemy/engine/base.py", line 2123, in contextual_connect
    self._wrap_pool_connect(self.pool.connect, None),
  File "/Users/levlaz/git/SupportService/venv/lib/python3.7/site-packages/sqlalchemy/engine/base.py", line 2162, in _wrap_pool_connect
    e, dialect, self)
  File "/Users/levlaz/git/SupportService/venv/lib/python3.7/site-packages/sqlalchemy/engine/base.py", line 1476, in _handle_dbapi_exception_noconnection
    exc_info
  File "/Users/levlaz/git/SupportService/venv/lib/python3.7/site-packages/sqlalchemy/util/compat.py", line 265, in raise_from_cause
    reraise(type(exception), exception, tb=exc_tb, cause=cause)
  File "/Users/levlaz/git/SupportService/venv/lib/python3.7/site-packages/sqlalchemy/util/compat.py", line 248, in reraise
    raise value.with_traceback(tb)
  File "/Users/levlaz/git/SupportService/venv/lib/python3.7/site-packages/sqlalchemy/engine/base.py", line 2158, in _wrap_pool_connect
    return fn()
  File "/Users/levlaz/git/SupportService/venv/lib/python3.7/site-packages/sqlalchemy/pool.py", line 400, in connect
    return _ConnectionFairy._checkout(self)
  File "/Users/levlaz/git/SupportService/venv/lib/python3.7/site-packages/sqlalchemy/pool.py", line 788, in _checkout
    fairy = _ConnectionRecord.checkout(pool)
  File "/Users/levlaz/git/SupportService/venv/lib/python3.7/site-packages/sqlalchemy/pool.py", line 529, in checkout
    rec = pool._do_get()
  File "/Users/levlaz/git/SupportService/venv/lib/python3.7/site-packages/sqlalchemy/pool.py", line 1193, in _do_get
    self._dec_overflow()
  File "/Users/levlaz/git/SupportService/venv/lib/python3.7/site-packages/sqlalchemy/util/langhelpers.py", line 66, in __exit__
    compat.reraise(exc_type, exc_value, exc_tb)
  File "/Users/levlaz/git/SupportService/venv/lib/python3.7/site-packages/sqlalchemy/util/compat.py", line 249, in reraise
    raise value
  File "/Users/levlaz/git/SupportService/venv/lib/python3.7/site-packages/sqlalchemy/pool.py", line 1190, in _do_get
    return self._create_connection()
  File "/Users/levlaz/git/SupportService/venv/lib/python3.7/site-packages/sqlalchemy/pool.py", line 347, in _create_connection
    return _ConnectionRecord(self)
  File "/Users/levlaz/git/SupportService/venv/lib/python3.7/site-packages/sqlalchemy/pool.py", line 474, in __init__
    self.__connect(first_connect_check=True)
  File "/Users/levlaz/git/SupportService/venv/lib/python3.7/site-packages/sqlalchemy/pool.py", line 671, in __connect
    connection = pool._invoke_creator(self)
  File "/Users/levlaz/git/SupportService/venv/lib/python3.7/site-packages/sqlalchemy/engine/strategies.py", line 106, in connect
    return dialect.connect(*cargs, **cparams)
  File "/Users/levlaz/git/SupportService/venv/lib/python3.7/site-packages/sqlalchemy/engine/default.py", line 412, in connect
    return self.dbapi.connect(*cargs, **cparams)
  File "/Users/levlaz/git/SupportService/venv/lib/python3.7/site-packages/psycopg2/__init__.py", line 130, in connect
    conn = _connect(dsn, connection_factory=connection_factory, **kwasync)
sqlalchemy.exc.OperationalError: (psycopg2.OperationalError) could not translate host name "db" to address: nodename nor servname provided, or not known
 (Background on this error at: http://sqlalche.me/e/e3q8)
]]>		</error>
	</testcase>
	<testcase classname="test_basics.BasicTestCase" name="test_app_is_testing" time="0.006" timestamp="2018-09-25T11:03:50">
		<error message="(psycopg2.OperationalError) could not translate host name &quot;db&quot; to address: nodename nor servname provided, or not known
 (Background on this error at: http://sqlalche.me/e/e3q8)" type="OperationalError">
<![CDATA[Traceback (most recent call last):
  File "/Users/levlaz/git/SupportService/venv/lib/python3.7/site-packages/sqlalchemy/engine/base.py", line 2158, in _wrap_pool_connect
    return fn()
  File "/Users/levlaz/git/SupportService/venv/lib/python3.7/site-packages/sqlalchemy/pool.py", line 400, in connect
    return _ConnectionFairy._checkout(self)
  File "/Users/levlaz/git/SupportService/venv/lib/python3.7/site-packages/sqlalchemy/pool.py", line 788, in _checkout
    fairy = _ConnectionRecord.checkout(pool)
  File "/Users/levlaz/git/SupportService/venv/lib/python3.7/site-packages/sqlalchemy/pool.py", line 529, in checkout
    rec = pool._do_get()
  File "/Users/levlaz/git/SupportService/venv/lib/python3.7/site-packages/sqlalchemy/pool.py", line 1193, in _do_get
    self._dec_overflow()
  File "/Users/levlaz/git/SupportService/venv/lib/python3.7/site-packages/sqlalchemy/util/langhelpers.py", line 66, in __exit__
    compat.reraise(exc_type, exc_value, exc_tb)
  File "/Users/levlaz/git/SupportService/venv/lib/python3.7/site-packages/sqlalchemy/util/compat.py", line 249, in reraise
    raise value
  File "/Users/levlaz/git/SupportService/venv/lib/python3.7/site-packages/sqlalchemy/pool.py", line 1190, in _do_get
    return self._create_connection()
  File "/Users/levlaz/git/SupportService/venv/lib/python3.7/site-packages/sqlalchemy/pool.py", line 347, in _create_connection
    return _ConnectionRecord(self)
  File "/Users/levlaz/git/SupportService/venv/lib/python3.7/site-packages/sqlalchemy/pool.py", line 474, in __init__
    self.__connect(first_connect_check=True)
  File "/Users/levlaz/git/SupportService/venv/lib/python3.7/site-packages/sqlalchemy/pool.py", line 671, in __connect
    connection = pool._invoke_creator(self)
  File "/Users/levlaz/git/SupportService/venv/lib/python3.7/site-packages/sqlalchemy/engine/strategies.py", line 106, in connect
    return dialect.connect(*cargs, **cparams)
  File "/Users/levlaz/git/SupportService/venv/lib/python3.7/site-packages/sqlalchemy/engine/default.py", line 412, in connect
    return self.dbapi.connect(*cargs, **cparams)
  File "/Users/levlaz/git/SupportService/venv/lib/python3.7/site-packages/psycopg2/__init__.py", line 130, in connect
    conn = _connect(dsn, connection_factory=connection_factory, **kwasync)
psycopg2.OperationalError: could not translate host name "db" to address: nodename nor servname provided, or not known


The above exception was the direct cause of the following exception:

Traceback (most recent call last):
  File "/Users/levlaz/git/SupportService/tests/test_basics.py", line 10, in setUp
    self.app = create_app('testing')
  File "/Users/levlaz/git/SupportService/app/factory.py", line 29, in create_app
    config[config_name].init_app(app)
  File "/Users/levlaz/git/SupportService/app/config.py", line 53, in init_app
    db.create_all()
  File "/Users/levlaz/git/SupportService/venv/lib/python3.7/site-packages/flask_sqlalchemy/__init__.py", line 963, in create_all
    self._execute_for_all_tables(app, bind, 'create_all')
  File "/Users/levlaz/git/SupportService/venv/lib/python3.7/site-packages/flask_sqlalchemy/__init__.py", line 955, in _execute_for_all_tables
    op(bind=self.get_engine(app, bind), **extra)
  File "/Users/levlaz/git/SupportService/venv/lib/python3.7/site-packages/sqlalchemy/sql/schema.py", line 4005, in create_all
    tables=tables)
  File "/Users/levlaz/git/SupportService/venv/lib/python3.7/site-packages/sqlalchemy/engine/base.py", line 1939, in _run_visitor
    with self._optional_conn_ctx_manager(connection) as conn:
  File "/usr/local/Cellar/python/3.7.0/Frameworks/Python.framework/Versions/3.7/lib/python3.7/contextlib.py", line 112, in __enter__
    return next(self.gen)
  File "/Users/levlaz/git/SupportService/venv/lib/python3.7/site-packages/sqlalchemy/engine/base.py", line 1932, in _optional_conn_ctx_manager
    with self.contextual_connect() as conn:
  File "/Users/levlaz/git/SupportService/venv/lib/python3.7/site-packages/sqlalchemy/engine/base.py", line 2123, in contextual_connect
    self._wrap_pool_connect(self.pool.connect, None),
  File "/Users/levlaz/git/SupportService/venv/lib/python3.7/site-packages/sqlalchemy/engine/base.py", line 2162, in _wrap_pool_connect
    e, dialect, self)
  File "/Users/levlaz/git/SupportService/venv/lib/python3.7/site-packages/sqlalchemy/engine/base.py", line 1476, in _handle_dbapi_exception_noconnection
    exc_info
  File "/Users/levlaz/git/SupportService/venv/lib/python3.7/site-packages/sqlalchemy/util/compat.py", line 265, in raise_from_cause
    reraise(type(exception), exception, tb=exc_tb, cause=cause)
  File "/Users/levlaz/git/SupportService/venv/lib/python3.7/site-packages/sqlalchemy/util/compat.py", line 248, in reraise
    raise value.with_traceback(tb)
  File "/Users/levlaz/git/SupportService/venv/lib/python3.7/site-packages/sqlalchemy/engine/base.py", line 2158, in _wrap_pool_connect
    return fn()
  File "/Users/levlaz/git/SupportService/venv/lib/python3.7/site-packages/sqlalchemy/pool.py", line 400, in connect
    return _ConnectionFairy._checkout(self)
  File "/Users/levlaz/git/SupportService/venv/lib/python3.7/site-packages/sqlalchemy/pool.py", line 788, in _checkout
    fairy = _ConnectionRecord.checkout(pool)
  File "/Users/levlaz/git/SupportService/venv/lib/python3.7/site-packages/sqlalchemy/pool.py", line 529, in checkout
    rec = pool._do_get()
  File "/Users/levlaz/git/SupportService/venv/lib/python3.7/site-packages/sqlalchemy/pool.py", line 1193, in _do_get
    self._dec_overflow()
  File "/Users/levlaz/git/SupportService/venv/lib/python3.7/site-packages/sqlalchemy/util/langhelpers.py", line 66, in __exit__
    compat.reraise(exc_type, exc_value, exc_tb)
  File "/Users/levlaz/git/SupportService/venv/lib/python3.7/site-packages/sqlalchemy/util/compat.py", line 249, in reraise
    raise value
  File "/Users/levlaz/git/SupportService/venv/lib/python3.7/site-packages/sqlalchemy/pool.py", line 1190, in _do_get
    return self._create_connection()
  File "/Users/levlaz/git/SupportService/venv/lib/python3.7/site-packages/sqlalchemy/pool.py", line 347, in _create_connection
    return _ConnectionRecord(self)
  File "/Users/levlaz/git/SupportService/venv/lib/python3.7/site-packages/sqlalchemy/pool.py", line 474, in __init__
    self.__connect(first_connect_check=True)
  File "/Users/levlaz/git/SupportService/venv/lib/python3.7/site-packages/sqlalchemy/pool.py", line 671, in __connect
    connection = pool._invoke_creator(self)
  File "/Users/levlaz/git/SupportService/venv/lib/python3.7/site-packages/sqlalchemy/engine/strategies.py", line 106, in connect
    return dialect.connect(*cargs, **cparams)
  File "/Users/levlaz/git/SupportService/venv/lib/python3.7/site-packages/sqlalchemy/engine/default.py", line 412, in connect
    return self.dbapi.connect(*cargs, **cparams)
  File "/Users/levlaz/git/SupportService/venv/lib/python3.7/site-packages/psycopg2/__init__.py", line 130, in connect
    conn = _connect(dsn, connection_factory=connection_factory, **kwasync)
sqlalchemy.exc.OperationalError: (psycopg2.OperationalError) could not translate host name "db" to address: nodename nor servname provided, or not known
 (Background on this error at: http://sqlalche.me/e/e3q8)
]]>		</error>
	</testcase>
	<system-out>
<![CDATA[]]>	</system-out>
	<system-err>
<![CDATA[]]>	</system-err>
</testsuite>
